Workbook

Sheet BGCorWB100
C3: Tanggal produksi | D3: Nama Produk | F3: SHOE UNYELLOWING - 13 | G3: Batch No. | I3: BLENDING GUIDE & SPKP
D4: No Resep | F4: 13 | G4: Tank No. | H4: 1
D5: Keterangan | F5: Formulator : Silmi | G5: Jumlah produksi/batch | I5: Versi | J5: : 1
B6: PT. MANDIRI INOVASI BERSAMA | D6: Jumlah Produksi (Kg) | F6: 100 | I6: Page | J6: : 1/1
B7: Resep | D7: TGL CETAK BG | F7: 45399
B8: No | C8: Nama barang | D8: SG (kg/l) | E8: Fomula (%b/b) | F8: Komposisi | H8: Disiapkan | I8: Dipakai | J8: Sisa
B9: 1 | C9: Aquadest | E9: =100-SUM(E10:E16) -> 76.1 | F9: =(E9/100)*$F$6 -> 76.1 | G9: Kg | H9: 11000 | I9: =E9*H9 -> 837100
B10: 2 | C10: PH 042 | E10: 0.7 | F10: =(E10/100)*$F$6 -> 0.7 | G10: Kg | I10: =E13*H10 -> 0
B11: 3 | C11: NX 127 | E11: 5 | F11: =(E11/100)*$F$6 -> 5 | G11: Kg | I11: =E14*H11 -> 0
B12: 4 | C12: AF 132 | E12: 0.4 | F12: =(E12/100)*$F$6 -> 0.4 | G12: Kg | I12: =E15*H12 -> 0
B13: 5 | C13: CL 120 | E13: 2.3 | F13: =(E13/100)*$F$6 -> 2.3 | G13: Kg | I13: =E11*H13 -> 0
B14: 6 | C14: SAPP | E14: 3 | F14: =(E14/100)*$F$6 -> 3 | G14: Kg | I14: =E10*H14 -> 0
B15: 7 | C15: ED 019 | E15: 0.5 | F15: =(E15/100)*$F$6 -> 0.5 | G15: Kg | I15: =E12*H15 -> 0
B16: 8 | C16: Hydrogen Peroxide 50% | E16: 12 | F16: =(E16/100)*$F$6 -> 12 | G16: Kg | I16: =E16*H16 -> 0
B17: 9 | I17: =E17*H17 -> 0
E18: =SUM(E9:E17) -> 100 | F18: =SUM(F9:F17) -> 100 | G18: Kg | I18: =SUM(I9:I17) -> 837100 | J18: =I18/100 -> 8371
B19: Pelindung diri | E19: Pail @20 L | F19: 5 | G19: Pcs
B20: 1 | C20: Kaca mata
B21: 2 | C21: Sepatu safety
B22: 3 | C22: Sarung tangan latex
B23: 4 | C23: Bahan kimia yang digunakan berbahaya
B24: Persiapan
B25: 1 | C25: Pastikan semua peralatan pelindung diri sudah terpakai
B26: 2 | C26: Pastikan semua peralatan produksi (mixer dan tangki) sudah bebas dari pengotor (air, oli, minyak, dan benda-benda asing lain)
B27: 3 | C27: Bila masih ditemukan pengotor, cuci peralatan dengan air sabun dan dibilas hingga bersih dan dikeringkan dengan majun
B28: 4 | C28: Siapkan semua BB yang akan dipakai sesuai resep
B29: 5 | C29: Lakukan QC semua BB (dilakukan oleh bagian QC, isi form di bawah)
B30: Cara produksi | O30: 44654
B31: 1 | C31: Masukkan Aquadest sebanyak komposisi yang terdapat pada formula BG ke dalam tangki mixer
B32: 2 | C32: Masukkan PH 042 sesuai komposisi, lalu aduk sampai merata/homogen
B33: 3 | C33: Masukkan NX 127 sesuai komposisi, lalu aduk sampai larut sempurna (warna putih merata)
B34: 4 | C34: Masukkan AF 132 sesuai komposisi, lalu aduk sampai larut sempurna (tidak ada gelembung)
B35: 5 | C35: Masukkan CL 120 sesuai komposisi BG, lalu mixing sampai merata/homogen
B36: 6 | C36: Masukkan SAPP sesuai komposisi BG, lalu aduk hingga mengental dan merata
B37: 7 | C37: Setelah campuran mengental, masukkan ED 019 sesuai komposisi hingga larut sempurna
B38: 8 | C38: Masukkan Hydrogen Peroxide 50% sesuai komposisi, lalu aduk hingga homogen
B39: 9 | C39: Ambil sample untuk cek QC
B40: 10 | C40: Jika OK, kemas sesuai kemasan yang sesuai
B42: Quality control | C42: (Diisi oleh bagian QC) | E42: Produk Jadi | G42: QC BB
C43: Parameter | D43: Teori | E43: Real | G43: No | H43: Nama barang | I43: QC Dec
...

Sheet Harga
B4: Product Name | C4: Shoe Unyellowing
B5: BG no
B6: Versi | C6: 2
B8: No | C8: Nama barang | D8: SG (kg/l) | E8: Komposisi (%b/b) | F8: Harga (rp) | G8: Price x formula (rp)
B9: 1 | C9: Hydrogen Peroxide 50 % ex korea | D9: 1.2 | E9: 100 | F9: 11000 | G9: =F9*E9 -> 1100000
B10: 2 | C10: TAED
B11: 3
B12: 4
B13: 5
B14: 4
E15: =SUM(E9:E14) -> 100 | G15: =SUM(G9:G14) -> 1100000 | H15: Rupiah/kg
F16: tenaga kerja | H16: Rupiah/kg
G17: =SUM(G15:G16)/E15 -> 11000
B18: VERSI 2
B19: Shoe Unyellowing | C19: per 100 ml | D19: =G17/10 -> 1100
B20: kemasan agro 100 ml | D20: 1500
B21: TAED 5 gram | C21: @2800 | D21: =5*2800 -> 14000
B22: Plastik klip | D22: 1000
E23: +
B24: total hpp | D24: =SUM(D19:D23) -> 17600
B25: margin 55% | D25: =D24*55% -> 9680 | E25: +
D26: =SUM(D24:D25) -> 27280
B27: Penawaran | D27: 28000 | E27: per set 100 ml | F27: 44565
B30: VERSI 3
B31: Shoe Unyellowing | C31: per 100 ml | D31: =G17/10 -> 1100
B32: kemasan agro 100 ml | D32: 1500
B33: TAED 1 gram | C33: @2800 | D33: =1*2800 -> 2800
B34: Plastik klip | D34: 1000
E35: +
B36: total hpp | D36: =SUM(D31:D35) -> 6400
B37: margin 100% | D37: =D36*100% -> 6400 | E37: +
D38: =SUM(D36:D37) -> 12800
B39: Penawaran | D39: 15000 | E39: per set 100 ml | F39: 44566
B42: VERSI 3
B43: Shoe Unyellowing | C43: per 100 ml | D43: 1100
B44: kemasan agro 100 ml | D44: 0
B45: TAED 1 gram | C45: @2800 | D45: =1*2800 -> 2800
B46: Plastik klip | D46: 1000
E47: +
B48: total hpp | D48: =SUM(D43:D47) -> 4900
...

Sheet Sheet1
A1: FORM PERMINTAAN BARANG KHUSUS
D3: Form Diminta untuk:
A4: Tanggal | B4: : | C4: =BGCorWB100!F7 -> 45399 | D4: Customer | E4: =BGCorWB100!F5 -> Formulator : Silmi | F4: Product | G4: =BGCorWB100!F3 -> SHOE UNYELLOWING - 13
A5: Dept | B5: : | C5: PPIC | D5: No. PO Cust | F5: Jumlah PO | G5: =BGCorWB100!F6 -> 100
D6: Tgl Turun PO | E6: =BGCorWB100!F7 -> 45399 | F6: Kemasan | G6: DRUM
D7: Target Kirim | F7: Isi Per Kemasan | G7: 200 | H7: L
A9: NO | B9: KodeBarang | D9: NamaBarang | F9: Qty | H9: Unit (L/KG)
A10: 1 | B10: =BGCorWB100!C16 -> Hydrogen Peroxide 50% | F10: =BGCorWB100!F9 -> 76.1 | H10: ='[1]BGCorWB100'!G9 -> #REF!
A11: 2 | B11: =BGCorWB100!C9 -> Aquadest | F11: =BGCorWB100!F10 -> 0.7 | H11: ='[1]BGCorWB100'!G10 -> #REF!
A12: 3 | B12: =BGCorWB100!C11 -> NX 127 | F12: =BGCorWB100!F11 -> 5 | H12: ='[1]BGCorWB100'!G11 -> #REF!
A13: 4 | B13: =BGCorWB100!#REF! -> #ERROR! | F13: =BGCorWB100!F12 -> 0.4 | H13: ='[1]BGCorWB100'!G12 -> #REF!
A14: 5 | B14: =BGCorWB100!C15 -> ED 019 | F14: =BGCorWB100!F13 -> 2.3 | H14: ='[1]BGCorWB100'!G13 -> #REF!
A15: 6 | B15: =BGCorWB100!#REF! -> #ERROR! | F15: =BGCorWB100!F14 -> 3 | H15: ='[1]BGCorWB100'!G14 -> #REF!
A16: 7 | B16: Kemasan | D16: =G6 -> DRUM | F16: =G5/G7 -> 0.5 | H16: pcs
A17: 8
A18: 9
A20: PPIC | E20: LOGISTIC
A23: ( | C23: ) | E23: ( | F23: )
