Workbook

Sheet BG Chlorine Bleach 01
C3: Tanggal produksi | D3: Nama Produk | F3: MIB Chlorine Bleach 01 | G3: Batch No. | I3: BLENDING GUIDE & SPKP
D4: No Resep | F4: 1 | G4: Tank No. | H4: 1
D5: Keterangan | F5: Bleach cleaner chlorine based | G5: Jumlah produksi/batch | I5: Versi | J5: : 1
B6: PT. MANDIRI INOVASI BERSAMA | D6: Jumlah Produksi (Kg) | F6: 1000 | I6: Page | J6: : 1/1
B7: Resep | D7: TGL CETAK BG | F7: 45491
B8: No | C8: Nama barang | D8: SG (kg/l) | E8: Fomula (%b/b) | F8: Komposisi | H8: Disiapkan | I8: Dipakai | J8: Sisa
B9: 1 | C9: Aquadest | E9: =100-SUM(E10:E13) -> 85.75 | F9: =(E9/100)*$F$6 -> 857.5 | G9: Kg | H9: 11000 | I9: =E9*H9 -> 943250
B10: 2 | C10: CF 091 | E10: 0.25 | F10: =(E10/100)*$F$6 -> 2.5 | G10: Kg | I10: =E13*H10 -> 0
B11: 3 | C11: SA 070 | E11: 1 | F11: =(E11/100)*$F$6 -> 10 | G11: Kg | I11: =E14*H11 -> 0
B12: 4 | C12: TX 193 | E12: 3 | F12: =(E12/100)*$F$6 -> 30 | G12: Kg | I12: =#REF!*H12 -> #REF!
B13: 5 | C13: SH 075 | E13: 10 | F13: =(E13/100)*$F$6 -> 100 | G13: Kg | I13: =E11*H13 -> 0
B14: 6 | F14: =(E14/100)*$F$6 -> 0 | G14: Kg | I14: =E10*H14 -> 0
B15: 9 | I15: =E15*H15 -> 0
E16: =SUM(E9:E15) -> 100 | F16: =SUM(F9:F15) -> 1000 | G16: Kg | I16: =SUM(I9:I15) -> #REF! | J16: =I16/100 -> #REF!
B17: Pelindung diri | E17: Pail @20 L | F17: 5 | G17: Pcs
B18: 1 | C18: Kaca mata
B19: 2 | C19: Sepatu safety
B20: 3 | C20: Sarung tangan latex
B21: 4 | C21: Bahan kimia yang digunakan berbahaya
B22: Persiapan
B23: 1 | C23: Pastikan semua peralatan pelindung diri sudah terpakai
B24: 2 | C24: Pastikan semua peralatan produksi (mixer dan tangki) sudah bebas dari pengotor (air, oli, minyak, dan benda-benda asing lain)
B25: 3 | C25: Bila masih ditemukan pengotor, cuci peralatan dengan air sabun dan dibilas hingga bersih dan dikeringkan dengan majun
B26: 4 | C26: Siapkan semua BB yang akan dipakai sesuai resep
B27: 5 | C27: Lakukan QC semua BB (dilakukan oleh bagian QC, isi form di bawah)
B28: Cara produksi | O28: 44654
B29: 1 | C29: Masukkan Aquadest sebanyak komposisi yang terdapat pada formula BG ke dalam tangki mixer
B30: 2 | C30: Masukkan CF 091 sesuai komposisi, lalu aduk sampai larut sempurna (tidak ada yang tersisa)
B31: 3 | C31: Masukkan SA 070 sesuai komposisi, lalu aduk sampai larut sempurna
B32: 4 | C32: Masukkan TX 193 sesuai komposisi, lalu aduk sampai larut sempurna (tidak ada gumpalan)
B33: 5 | C33: Masukkan SH 075 sesuai komposisi BG, lalu aduk sampai larut sempurna
B34: 6 | C34: Ambil sample untuk cek QC
B35: 7 | C35: Jika OK, kemas sesuai kemasan yang sesuai
B37: Quality control | C37: (Diisi oleh bagian QC) | E37: Produk Jadi | G37: QC BB
C38: Parameter | D38: Teori | E38: Real | G38: No | H38: Nama barang | I38: QC Dec
B39: 1 | C39: pH | D39: 12-13 | G39: 1 | H39: =#REF! -> #REF!
B40: 2 | C40: Warna | D40: Transparant colorless to yellowish | G40: 2 | H40: =C9 -> Aquadest
B41: 3 | C41: Densitas | D41: 1,01 - 1,03 | G41: 3 | H41: =C11 -> SA 070
B42: 4 | C42: Uji peroxide strip | D42: Biru | G42: 4 | H42: =C12 -> TX 193
B43: 5 | G43: 5 | H43: =#REF! -> #REF!
...

Sheet Sheet1
A1: FORM PERMINTAAN BARANG KHUSUS
D3: Form Diminta untuk:
A4: Tanggal | B4: : | C4: ='BG Chlorine Bleach 01'!F7 -> 45491 | D4: Customer | E4: ='BG Chlorine Bleach 01'!F5 -> Bleach cleaner chlorine based | F4: Product | G4: ='BG Chlorine Bleach 01'!F3 -> MIB Chlorine Bleach 01
A5: Dept | B5: : | C5: PPIC | D5: No. PO Cust | F5: Jumlah PO | G5: ='BG Chlorine Bleach 01'!F6 -> 1000
D6: Tgl Turun PO | E6: ='BG Chlorine Bleach 01'!F7 -> 45491 | F6: Kemasan | G6: DRUM
D7: Target Kirim | F7: Isi Per Kemasan | G7: 200 | H7: L
A9: NO | B9: KodeBarang | D9: NamaBarang | F9: Qty | H9: Unit (L/KG)
A10: 1 | B10: ='BG Chlorine Bleach 01'!#REF! -> #ERROR! | F10: ='BG Chlorine Bleach 01'!F9 -> 857.5 | H10: ='[1]BGCorWB100'!G9 -> #REF!
A11: 2 | B11: ='BG Chlorine Bleach 01'!C9 -> Aquadest | F11: ='BG Chlorine Bleach 01'!F10 -> 2.5 | H11: ='[1]BGCorWB100'!G10 -> #REF!
A12: 3 | B12: ='BG Chlorine Bleach 01'!C11 -> SA 070 | F12: ='BG Chlorine Bleach 01'!F11 -> 10 | H12: ='[1]BGCorWB100'!G11 -> #REF!
A13: 4 | B13: ='BG Chlorine Bleach 01'!#REF! -> #ERROR! | F13: ='BG Chlorine Bleach 01'!F12 -> 30 | H13: ='[1]BGCorWB100'!G12 -> #REF!
A14: 5 | B14: ='BG Chlorine Bleach 01'!#REF! -> #ERROR! | F14: ='BG Chlorine Bleach 01'!F13 -> 100 | H14: ='[1]BGCorWB100'!G13 -> #REF!
A15: 6 | B15: ='BG Chlorine Bleach 01'!#REF! -> #ERROR! | F15: ='BG Chlorine Bleach 01'!F14 -> 0 | H15: ='[1]BGCorWB100'!G14 -> #REF!
A16: 7 | B16: Kemasan | D16: =G6 -> DRUM | F16: =G5/G7 -> 5 | H16: pcs
A17: 8
A18: 9
A20: PPIC | E20: LOGISTIC
A23: ( | C23: ) | E23: ( | F23: )
