Workbook

Sheet BG MIB Boil Clean - Acid Based
C3: Tanggal produksi | D3: Nama Produk | F3: MIB Boil Cleaner - Acid Based | G3: Batch No. | H3: 12.02.25.T3-01 | I3: BLENDING GUIDE & SPKP
D4: No Resep | F4: 1 | G4: Tank No. | H4: T3
D5: Keterangan | F5: scale and corrosion cleaner for boiler - Acid Based | G5: Jumlah produksi/batch | I5: Versi | J5: : 1
B6: PT. MANDIRI INOVASI BERSAMA | D6: Jumlah Produksi (Kg) | F6: 1000 | I6: Page | J6: : 1/1
B7: Resep | D7: TGL CETAK BG | F7: 45497
B8: No | C8: Nama barang | D8: SG (kg/l) | E8: Fomula (%b/b) | F8: Komposisi | H8: Disiapkan | I8: Dipakai | J8: Sisa
B9: 1 | C9: Aquadest | E9: =100-SUM(E10:E14) -> 42.8 | F9: =(E9/100)*$F$6 -> 42.8 | G9: Kg | H9: 11000 | I9: =E9*H9 -> 470800
B10: 2 | C10: NP 033 | E10: 3 | F10: =(E10/100)*$F$6 -> 3 | G10: Kg | I10: =E13*H10 -> 0
B11: 3 | C11: AB 081 | E11: 5 | F11: =(E11/100)*$F$6 -> 5 | G11: Kg | I11: =E14*H11 -> 0
B12: 4 | C12: HC 078 | E12: 45 | F12: =(E12/100)*$F$6 -> 45 | G12: Kg | I12: =#REF!*H12 -> #REF!
B13: 5 | C13: Armohib 28 | E13: 0.2 | F13: =(E13/100)*$F$6 -> 0.2 | G13: Kg | I13: =E11*H13 -> 0
B14: 6 | C14: HE 140 | E14: 4 | F14: =(E14/100)*$F$6 -> 4 | I14: =E10*H14 -> 0
I15: =E15*H15 -> 0
E16: =SUM(E9:E15) -> 100 | F16: =SUM(F9:F15) -> 100 | G16: Kg | I16: =SUM(I9:I15) -> #REF! | J16: =I16/100 -> #REF!
B17: Pelindung diri | E17: Pail @25 L | F17: 5 | G17: Pcs
B18: 1 | C18: Kaca mata
B19: 2 | C19: Sepatu safety
B20: 3 | C20: Sarung tangan latex
B21: 4 | C21: Bahan kimia yang digunakan berbahaya
B22: Persiapan
B23: 1 | C23: Pastikan semua peralatan pelindung diri sudah terpakai
B24: 2 | C24: Pastikan semua peralatan produksi (mixer dan tangki) sudah bebas dari pengotor (air, oli, minyak, dan benda-benda asing lain)
B25: 3 | C25: Bila masih ditemukan pengotor, cuci peralatan dengan air sabun dan dibilas hingga bersih dan dikeringkan dengan majun
B26: 4 | C26: Siapkan semua BB yang akan dipakai sesuai resep
B27: 5 | C27: Lakukan QC semua BB (dilakukan oleh bagian QC, isi form di bawah)
B28: Cara produksi | O28: 44654
B29: 1 | C29: Masukkan Aquadest sebanyak komposisi yang terdapat pada formula BG ke dalam tangki mixer
B30: 2 | C30: Masukkan NP 033 sesuai komposisi, lalu aduk sampai larut seumpurna (Tidak ada gumpalan)
B31: 3 | C31: Masukkan AB 081 sesuai komposisi, lalu aduk sampai larut sempurna
B32: 4 | C32: Masukkan HC 078 sesuai komposisi, lalu aduk hingga larut sempurna
B33: 5 | C33: Masukkan Armohib 28 sesuai komposisi BG, lalu aduk sampai larut sempurna (tidak ada gumpalan)
B34: 6 | C34: Masukkan HE 140 sesuai komposisi BG, lalu aduk sampai larut sempurna (tidak ada endapan) dan larutan bening sempurna
B35: 7 | C35: Ambil sample untuk cek QC
B36: 8 | C36: Jika OK, kemas sesuai kemasan yang sesuai
B38: Quality control | C38: (Diisi oleh bagian QC) | E38: Produk Jadi | G38: QC BB
C39: Parameter | D39: Teori | E39: Real | G39: No | H39: Nama barang | I39: QC Dec
B40: 1 | C40: pH | D40: 0-1 | G40: 1 | H40: =#REF! -> #REF!
B41: 2 | C41: Warna | D41: Clear Transparant | G41: 2 | H41: =C9 -> Aquadest
B42: 3 | C42: Densitas | D42: 1,10 - 1,12 | G42: 3 | H42: =C11 -> AB 081
B43: 4 | G43: 4 | H43: =C10 -> NP 033
...

Sheet Sheet1
A1: FORM PERMINTAAN BARANG KHUSUS
D3: Form Diminta untuk:
A4: Tanggal | B4: : | C4: ='BG MIB Boil Clean - Acid Based'!F7 -> 45497 | D4: Customer | E4: ='BG MIB Boil Clean - Acid Based'!F5 -> scale and corrosion cleaner for boiler - Acid Based | F4: Product | G4: ='BG MIB Boil Clean - Acid Based'!F3 -> MIB Boil Cleaner - Acid Based
A5: Dept | B5: : | C5: PPIC | D5: No. PO Cust | F5: Jumlah PO | G5: ='BG MIB Boil Clean - Acid Based'!F6 -> 100
D6: Tgl Turun PO | E6: ='BG MIB Boil Clean - Acid Based'!F7 -> 45497 | F6: Kemasan | G6: DRUM
D7: Target Kirim | F7: Isi Per Kemasan | G7: 200 | H7: L
A9: NO | B9: KodeBarang | D9: NamaBarang | F9: Qty | H9: Unit (L/KG)
A10: 1 | B10: ='BG MIB Boil Clean - Acid Based'!#REF! -> #ERROR! | F10: ='BG MIB Boil Clean - Acid Based'!F9 -> 42.8 | H10: ='[1]BGCorWB100'!G9 -> #REF!
A11: 2 | B11: ='BG MIB Boil Clean - Acid Based'!C9 -> Aquadest | F11: ='BG MIB Boil Clean - Acid Based'!F10 -> 3 | H11: ='[1]BGCorWB100'!G10 -> #REF!
A12: 3 | B12: ='BG MIB Boil Clean - Acid Based'!C11 -> AB 081 | F12: ='BG MIB Boil Clean - Acid Based'!F11 -> 5 | H12: ='[1]BGCorWB100'!G11 -> #REF!
A13: 4 | B13: ='BG MIB Boil Clean - Acid Based'!#REF! -> #ERROR! | F13: ='BG MIB Boil Clean - Acid Based'!F12 -> 45 | H13: ='[1]BGCorWB100'!G12 -> #REF!
A14: 5 | B14: ='BG MIB Boil Clean - Acid Based'!#REF! -> #ERROR! | F14: ='BG MIB Boil Clean - Acid Based'!F13 -> 0.2 | H14: ='[1]BGCorWB100'!G13 -> #REF!
A15: 6 | B15: ='BG MIB Boil Clean - Acid Based'!#REF! -> #ERROR! | F15: ='BG MIB Boil Clean - Acid Based'!F14 -> 4 | H15: ='[1]BGCorWB100'!G14 -> #REF!
A16: 7 | B16: Kemasan | D16: =G6 -> DRUM | F16: =G5/G7 -> 0.5 | H16: pcs
A17: 8
A18: 9
A20: PPIC | E20: LOGISTIC
A23: ( | C23: ) | E23: ( | F23: )
