Workbook

Sheet BG_ChemX 119266 A
C3: Tanggal produksi | D3: Nama Produk | F3: ChemX 119266 A | G3: Batch No. | H3: 22.02.25.Tank 5-01 | I3: BLENDING GUIDE & SPKP
D4: No Resep | F4: 002/BG/MIB/II-24 | G4: Tank No. | H4: Tank 5
D5: Keterangan | F5: ITS - 428Wn/ITS-PO/I/2025 | G5: Jumlah produksi/batch | I5: Versi | J5: : 2
B6: PT. Mandiri Inovasi Bersama | D6: Jumlah Produksi (kg) | E6: 100 | F6: 7888 | I6: Page | J6: : 1/1
B7: Resep | D7: Tgl Cetak BG | F7: 45677
B8: No | C8: Nama barang | D8: SG (kg/l) | E8: Fomula (%b/b) | F8: Komposisi (kg) | H8: Disiapkan | I8: Dipakai | J8: Sisa
B9: 1 | C9: Air | E9: 68.5 | F9: =(E9/100)*$F$6 -> 137 | G9: gr | H9: 300 | I9: =E9*H9 -> 20550
B10: 2 | C10: PA 139 | E10: 16.1 | F10: =(E10/100)*$F$6 -> 32.2 | G10: gr | H10: 18000 | I10: =E10*H10 -> 289800
B11: 3 | C11: CF 091 | E11: 8 | F11: =(E11/100)*$F$6 -> 16 | G11: gr | H11: 22000 | I11: =E11*H11 -> 176000
B12: 4 | C12: HE 140 | E12: 6 | F12: =(E12/100)*$F$6 -> 12 | G12: gr | H12: 265000 | I12: =E12*H12 -> 1590000
B13: 5 | C13: TT 092 | E13: 1.4 | F13: =(E13/100)*$F$6 -> 2.8 | G13: gr | H13: 14500 | I13: =E13*H13 -> 20300 | J13: BC Sagara
D14: 1 | H14: 55000 | I14: =E14*H14 -> 0
E15: Total | F15: =SUM(F9:F14) -> 200 | I15: =SUM(I9:I14) -> 2096650 | J15: =I15/100 -> 20966.5
B16: Pelindung diri
B17: 1 | C17: Kaca mata
B18: 2 | C18: Sepatu safety
B19: 3 | C19: Sarung tangan karet
B20: 4 | C20: Semua bahan kimia yang digunakan tidak berbahaya
B21: Persiapan
B22: 1 | C22: Pastikan semua peralatan pelindung diri sudah terpakai
B23: 2 | C23: Pastikan semua peralatan produksi (mixer dan tangki) sudah bebas dari pengotor (air, oli, minyak, dan benda-benda asing lain)
B24: 3 | C24: Bila masih ditemukan pengotor, cuci peralatan dengan air sabun dan dibilas hingga bersih dan dikeringkan dengan majun
B25: 4 | C25: Siapkan semua BB yang akan dipakai sesuai resep
B26: 5 | C26: Lakukan QC semua BB (dilakukan oleh bagian QC, isi form di bawah)
B27: Cara produksi
B28: 1 | C28: Timbang air sebanyak yang dibutuhkan dan masukan dalam tangki pengadukan
B29: 2 | C29: Masukan CF 091 dan TT 092 aduk sampai larut dan bening
B30: 3 | C30: Tambahkan HE 140 aduk sampai larut
B31: 4 | C31: Terakhir masukan PA 139 aduk sampai larut dan bening
B32: 5 | C32: Bila sudah selesai ambil sampel untuk analisa lab
B33: 6 | C33: Bila hasil lab OK, kemas sesuai kebutuhan
B34: Quality control | C34: (Diisi oleh bagian QC Lab.) | E34: Produk Jadi | G34: QC BB
C35: Parameter | D35: Teori | E35: Real | G35: No | H35: Nama barang | I35: QC Dec
B36: 1 | C36: Tampilan | D36: Cair bening | G36: 1 | H36: PA 139
B37: 2 | C37: pH | D37: 12.00-13.00 | G37: 2 | H37: CF 091
B38: 3 | C38: SG | D38: 1.05-1.07 | G38: 3 | H38: HE 140
B39: 4 | C39: Busa | G39: 4 | H39: TT 092
B40: 5 | C40: Warna | D40: - | G40: 5
B41: 6 | C41: Aroma | G41: 6
G42: 7
...

Sheet Sheet1
A1: FORM PERMINTAAN BARANG KHUSUS
D3: Form Diminta untuk:
A4: Tanggal | B4: : | C4: ='BG_ChemX 119266 A'!F7 -> 45677 | D4: Customer | E4: ='BG_ChemX 119266 A'!F5 -> ITS - 428Wn/ITS-PO/I/2025 | F4: Product | G4: ='BG_ChemX 119266 A'!F3 -> ChemX 119266 A
A5: Dept | B5: : | C5: PPIC | D5: No. PO Cust | F5: Jumlah PO | G5: ='BG_ChemX 119266 A'!F6 -> 200
D6: Tgl Turun PO | F6: Kemasan | G6: Jerigen Putih susu
D7: Target Kirim | F7: Isi Per Kemasan | G7: 20 | H7: liter
A9: NO | B9: KodeBarang | D9: NamaBarang | F9: Qty | H9: Unit (KG)
A10: 1 | B10: ='BG_ChemX 119266 A'!C9 -> Air | F10: ='BG_ChemX 119266 A'!F9 -> 137 | H10: gr
A11: 2 | B11: ='BG_ChemX 119266 A'!C10 -> PA 139 | F11: ='BG_ChemX 119266 A'!F10 -> 32.2 | H11: gr
A12: 3 | B12: ='BG_ChemX 119266 A'!C11 -> CF 091 | F12: ='BG_ChemX 119266 A'!F11 -> 16 | H12: gr
A13: 4 | B13: ='BG_ChemX 119266 A'!C12 -> HE 140 | F13: ='BG_ChemX 119266 A'!F12 -> 12 | H13: gr
A14: 5 | B14: ='BG_ChemX 119266 A'!C13 -> TT 092 | F14: ='BG_ChemX 119266 A'!F13 -> 2.8 | H14: gr
A15: 6 | B15: Kemasan | D15: =G6 -> Jerigen Putih susu | F15: =G5/G7 -> 10 | H15: pc
A17: PPIC | E17: LOGISTIC
A20: ( | C20: ) | E20: ( | F20: )
A23: FORM PERMINTAAN BARANG KHUSUS
D25: Form Diminta untuk:
A26: Tanggal | B26: : | D26: Customer | E26: : | F26: Product | G26: :
A27: Dept | B27: : | D27: No. PO Cust | E27: : | F27: Jumlah PO | G27: :
D28: Tgl Turun PO | E28: : | F28: Kemasan | G28: :
D29: Target Kirim | E29: : | F29: Isi Per Kemasan | G29: :
A31: NO | B31: KodeBarang | D31: NamaBarang | F31: Qty | H31: Unit (L/KG)
A32: 1
A33: 2
A34: 3
A35: 4
A36: 5
A37: 6
A38: 7
A39: 8
A40: 9
A41: 10
A43: PPIC | E43: LOGISTIC
A46: ( | C46: ) | E46: ( | F46: )
